[2024-03-24 13:41:38,803: INFO: main: Welcome to our custom log]
[2024-03-26 00:08:29,197: INFO: common: yaml file: config\config.yaml loaded successfully]
[2024-03-26 00:08:29,557: INFO: common: yaml file: params.yaml loaded successfully]
[2024-03-26 00:08:29,561: INFO: common: created directory at: artifacts]
[2024-03-26 00:11:42,487: INFO: common: yaml file: config\config.yaml loaded successfully]
[2024-03-26 00:11:42,489: INFO: common: yaml file: params.yaml loaded successfully]
[2024-03-26 00:11:42,490: INFO: common: created directory at: artifacts]
[2024-03-26 00:11:42,492: INFO: common: created directory at: artifacts/data_ingestion]
[2024-03-26 00:11:42,495: INFO: 986331348: Downloading data from https://drive.google.com/file/d/1vlhZ5c7abUKF8xXERIw6m9Te8fW7ohw3/view?usp=sharing into file artifacts/data_ingestion/data.zip]
[2024-03-26 00:12:02,388: INFO: 986331348: Downloaded data from https://drive.google.com/file/d/1vlhZ5c7abUKF8xXERIw6m9Te8fW7ohw3/view?usp=sharing into file artifacts/data_ingestion/data.zip]
[2024-03-26 00:53:25,431: INFO: main: >>>>>> stage Data Ingestion stage started <<<<<<]
[2024-03-26 00:53:25,443: INFO: common: yaml file: config\config.yaml loaded successfully]
[2024-03-26 00:53:25,444: INFO: common: yaml file: params.yaml loaded successfully]
[2024-03-26 00:53:25,445: INFO: common: created directory at: artifacts]
[2024-03-26 00:53:25,445: INFO: common: created directory at: artifacts/data_ingestion]
[2024-03-26 00:53:25,446: INFO: data_ingestion: Downloading data from https://drive.google.com/file/d/1vlhZ5c7abUKF8xXERIw6m9Te8fW7ohw3/view?usp=sharing into file artifacts/data_ingestion/data.zip]
[2024-03-26 00:53:37,505: INFO: data_ingestion: Downloaded data from https://drive.google.com/file/d/1vlhZ5c7abUKF8xXERIw6m9Te8fW7ohw3/view?usp=sharing into file artifacts/data_ingestion/data.zip]
[2024-03-26 00:53:38,188: INFO: main: >>>>>> stage Data Ingestion stage completed <<<<<<

x==========x]
[2024-03-26 01:29:42,609: INFO: common: yaml file: config\config.yaml loaded successfully]
[2024-03-26 01:29:42,614: INFO: common: yaml file: params.yaml loaded successfully]
[2024-03-26 01:29:42,630: INFO: common: created directory at: artifacts]
[2024-03-26 01:33:17,389: INFO: common: yaml file: config\config.yaml loaded successfully]
[2024-03-26 01:33:17,393: INFO: common: yaml file: params.yaml loaded successfully]
[2024-03-26 01:33:17,395: INFO: common: created directory at: artifacts]
[2024-03-26 01:33:17,397: INFO: common: created directory at: artifacts/prepare_base_model]
[2024-03-26 01:33:19,697: WARNING: saving_utils: Compiled the loaded model, but the compiled metrics have yet to be built. `model.compile_metrics` will be empty until you train or evaluate the model.]
[2024-03-26 01:43:35,218: INFO: main: >>>>>> stage Data Ingestion stage started <<<<<<]
[2024-03-26 01:43:35,236: INFO: common: yaml file: config\config.yaml loaded successfully]
[2024-03-26 01:43:35,238: INFO: common: yaml file: params.yaml loaded successfully]
[2024-03-26 01:43:35,239: INFO: common: created directory at: artifacts]
[2024-03-26 01:43:35,239: INFO: common: created directory at: artifacts/data_ingestion]
[2024-03-26 01:43:35,240: INFO: data_ingestion: Downloading data from https://drive.google.com/file/d/1vlhZ5c7abUKF8xXERIw6m9Te8fW7ohw3/view?usp=sharing into file artifacts/data_ingestion/data.zip]
[2024-03-26 01:43:48,519: INFO: data_ingestion: Downloaded data from https://drive.google.com/file/d/1vlhZ5c7abUKF8xXERIw6m9Te8fW7ohw3/view?usp=sharing into file artifacts/data_ingestion/data.zip]
[2024-03-26 01:43:49,168: INFO: main: >>>>>> stage Data Ingestion stage completed <<<<<<

x==========x]
[2024-03-26 01:43:49,168: INFO: main: *******************]
[2024-03-26 01:43:49,168: INFO: main: >>>>>> stage Prepare base model started <<<<<<]
[2024-03-26 01:43:49,170: INFO: common: yaml file: config\config.yaml loaded successfully]
[2024-03-26 01:43:49,172: INFO: common: yaml file: params.yaml loaded successfully]
[2024-03-26 01:43:49,173: INFO: common: created directory at: artifacts]
[2024-03-26 01:43:49,174: INFO: common: created directory at: artifacts/prepare_base_model]
[2024-03-26 01:43:49,710: WARNING: saving_utils: Compiled the loaded model, but the compiled metrics have yet to be built. `model.compile_metrics` will be empty until you train or evaluate the model.]
[2024-03-26 01:43:50,978: INFO: main: >>>>>> stage Prepare base model completed <<<<<<

x==========x]
[2024-03-26 22:08:06,015: INFO: common: yaml file: config\config.yaml loaded successfully]
[2024-03-26 22:08:06,074: INFO: common: yaml file: params.yaml loaded successfully]
[2024-03-26 22:08:06,087: INFO: common: created directory at: artifacts]
[2024-03-26 22:08:06,089: INFO: common: created directory at: artifacts\training]
[2024-03-26 22:44:31,590: INFO: main: >>>>>> stage Data Ingestion stage started <<<<<<]
[2024-03-26 22:44:31,594: INFO: common: yaml file: config\config.yaml loaded successfully]
[2024-03-26 22:44:31,610: INFO: common: yaml file: params.yaml loaded successfully]
[2024-03-26 22:44:31,624: INFO: common: created directory at: artifacts]
[2024-03-26 22:44:31,625: INFO: common: created directory at: artifacts/data_ingestion]
[2024-03-26 22:44:31,625: INFO: data_ingestion: Downloading data from https://drive.google.com/file/d/1vlhZ5c7abUKF8xXERIw6m9Te8fW7ohw3/view?usp=sharing into file artifacts/data_ingestion/data.zip]
[2024-03-26 22:44:47,343: INFO: data_ingestion: Downloaded data from https://drive.google.com/file/d/1vlhZ5c7abUKF8xXERIw6m9Te8fW7ohw3/view?usp=sharing into file artifacts/data_ingestion/data.zip]
[2024-03-26 22:44:48,445: INFO: main: >>>>>> stage Data Ingestion stage completed <<<<<<

x==========x]
[2024-03-26 22:44:48,446: INFO: main: *******************]
[2024-03-26 22:44:48,448: INFO: main: >>>>>> stage Prepare base model started <<<<<<]
[2024-03-26 22:44:48,450: INFO: common: yaml file: config\config.yaml loaded successfully]
[2024-03-26 22:44:48,453: INFO: common: yaml file: params.yaml loaded successfully]
[2024-03-26 22:44:48,454: INFO: common: created directory at: artifacts]
[2024-03-26 22:44:48,454: INFO: common: created directory at: artifacts/prepare_base_model]
[2024-03-26 22:44:49,559: WARNING: saving_utils: Compiled the loaded model, but the compiled metrics have yet to be built. `model.compile_metrics` will be empty until you train or evaluate the model.]
[2024-03-26 22:44:50,563: INFO: main: >>>>>> stage Prepare base model completed <<<<<<

x==========x]
[2024-03-26 22:44:50,564: INFO: main: *******************]
[2024-03-26 22:44:50,565: INFO: main: >>>>>> stage Training started <<<<<<]
[2024-03-26 22:44:50,573: INFO: common: yaml file: config\config.yaml loaded successfully]
[2024-03-26 22:44:50,579: INFO: common: yaml file: params.yaml loaded successfully]
[2024-03-26 22:44:50,581: INFO: common: created directory at: artifacts]
[2024-03-26 22:44:50,582: INFO: common: created directory at: artifacts\training]
[2024-03-26 22:46:08,243: INFO: main: >>>>>> stage Training completed <<<<<<

x==========x]
[2024-03-27 17:31:09,016: INFO: common: yaml file: config\config.yaml loaded successfully]
[2024-03-27 17:31:09,138: INFO: common: yaml file: params.yaml loaded successfully]
[2024-03-27 17:31:09,145: INFO: common: created directory at: artifacts]
[2024-03-27 17:31:41,280: INFO: common: json file saved at: scores.json]
[2024-03-27 17:31:49,466: WARNING: save: Found untraced functions such as _jit_compiled_convolution_op, _jit_compiled_convolution_op, _jit_compiled_convolution_op, _jit_compiled_convolution_op, _jit_compiled_convolution_op while saving (showing 5 of 14). These functions will not be directly callable after loading.]
[2024-03-27 17:31:53,200: INFO: builder_impl: Assets written to: C:\Users\PAKSHA~1\AppData\Local\Temp\tmpn3wdoc8f\model\data\model\assets]
[2024-03-27 17:42:23,077: INFO: common: yaml file: config\config.yaml loaded successfully]
[2024-03-27 17:42:23,170: INFO: common: yaml file: params.yaml loaded successfully]
[2024-03-27 17:42:23,174: INFO: common: created directory at: artifacts]
[2024-03-27 17:42:48,746: INFO: common: json file saved at: scores.json]
[2024-03-27 17:42:53,468: WARNING: save: Found untraced functions such as _jit_compiled_convolution_op, _jit_compiled_convolution_op, _jit_compiled_convolution_op, _jit_compiled_convolution_op, _jit_compiled_convolution_op while saving (showing 5 of 14). These functions will not be directly callable after loading.]
[2024-03-27 17:42:54,595: INFO: builder_impl: Assets written to: C:\Users\PAKSHA~1\AppData\Local\Temp\tmpzzr45fgl\model\data\model\assets]
[2024-03-27 18:00:24,626: INFO: main: >>>>>> stage Data Ingestion stage started <<<<<<]
[2024-03-27 18:00:24,964: INFO: common: yaml file: config\config.yaml loaded successfully]
[2024-03-27 18:00:24,972: INFO: common: yaml file: params.yaml loaded successfully]
[2024-03-27 18:00:25,189: INFO: common: created directory at: artifacts]
[2024-03-27 18:00:25,191: INFO: common: created directory at: artifacts/data_ingestion]
[2024-03-27 18:00:25,193: INFO: data_ingestion: Downloading data from https://drive.google.com/file/d/1vlhZ5c7abUKF8xXERIw6m9Te8fW7ohw3/view?usp=sharing into file artifacts/data_ingestion/data.zip]
[2024-03-27 18:00:38,144: INFO: data_ingestion: Downloaded data from https://drive.google.com/file/d/1vlhZ5c7abUKF8xXERIw6m9Te8fW7ohw3/view?usp=sharing into file artifacts/data_ingestion/data.zip]
[2024-03-27 18:00:38,959: INFO: main: >>>>>> stage Data Ingestion stage completed <<<<<<

x==========x]
[2024-03-27 18:00:38,959: INFO: main: *******************]
[2024-03-27 18:00:38,960: INFO: main: >>>>>> stage Prepare base model started <<<<<<]
[2024-03-27 18:00:38,963: INFO: common: yaml file: config\config.yaml loaded successfully]
[2024-03-27 18:00:38,965: INFO: common: yaml file: params.yaml loaded successfully]
[2024-03-27 18:00:38,966: INFO: common: created directory at: artifacts]
[2024-03-27 18:00:38,967: INFO: common: created directory at: artifacts/prepare_base_model]
[2024-03-27 18:00:39,547: WARNING: saving_utils: Compiled the loaded model, but the compiled metrics have yet to be built. `model.compile_metrics` will be empty until you train or evaluate the model.]
[2024-03-27 18:00:40,007: INFO: main: >>>>>> stage Prepare base model completed <<<<<<

x==========x]
[2024-03-27 18:00:40,008: INFO: main: *******************]
[2024-03-27 18:00:40,009: INFO: main: >>>>>> stage Training started <<<<<<]
[2024-03-27 18:00:40,013: INFO: common: yaml file: config\config.yaml loaded successfully]
[2024-03-27 18:00:40,015: INFO: common: yaml file: params.yaml loaded successfully]
[2024-03-27 18:00:40,016: INFO: common: created directory at: artifacts]
[2024-03-27 18:00:40,017: INFO: common: created directory at: artifacts\training]
[2024-03-27 18:03:24,535: INFO: main: >>>>>> stage Training completed <<<<<<

x==========x]
[2024-03-27 18:03:24,536: INFO: main: *******************]
[2024-03-27 18:03:24,537: INFO: main: >>>>>> stage Evaluation stage started <<<<<<]
[2024-03-27 18:03:24,541: INFO: common: yaml file: config\config.yaml loaded successfully]
[2024-03-27 18:03:24,544: INFO: common: yaml file: params.yaml loaded successfully]
[2024-03-27 18:03:24,545: INFO: common: created directory at: artifacts]
[2024-03-27 18:03:54,625: INFO: common: json file saved at: scores.json]
[2024-03-27 18:03:54,627: INFO: common: json file saved at: scores.json]
[2024-03-27 18:03:54,628: INFO: main: >>>>>> stage Evaluation stage completed <<<<<<

x==========x]
[2024-03-27 18:34:41,484: INFO: stage_01_data_ingestion: >>>>>> stage Data Ingestion Stage started <<<<<<]
[2024-03-27 18:34:41,486: INFO: common: yaml file: config\config.yaml loaded successfully]
[2024-03-27 18:34:41,489: INFO: common: yaml file: params.yaml loaded successfully]
[2024-03-27 18:34:41,489: INFO: common: created directory at: artifacts]
[2024-03-27 18:34:41,489: INFO: common: created directory at: artifacts/data_ingestion]
[2024-03-27 18:34:41,490: INFO: data_ingestion: Downloading data from https://drive.google.com/file/d/1vlhZ5c7abUKF8xXERIw6m9Te8fW7ohw3/view?usp=sharing into file artifacts/data_ingestion/data.zip]
[2024-03-27 18:34:54,467: INFO: data_ingestion: Downloaded data from https://drive.google.com/file/d/1vlhZ5c7abUKF8xXERIw6m9Te8fW7ohw3/view?usp=sharing into file artifacts/data_ingestion/data.zip]
[2024-03-27 18:34:55,139: INFO: stage_01_data_ingestion: >>>>>> stage Data Ingestion Stage completed <<<<<<

x==========x]
[2024-03-27 18:35:08,452: INFO: stage_02_prepare_base_model: *******************]
[2024-03-27 18:35:08,453: INFO: stage_02_prepare_base_model: >>>>>> stage Prepare base model started <<<<<<]
[2024-03-27 18:35:08,457: INFO: common: yaml file: config\config.yaml loaded successfully]
[2024-03-27 18:35:08,459: INFO: common: yaml file: params.yaml loaded successfully]
[2024-03-27 18:35:08,460: INFO: common: created directory at: artifacts]
[2024-03-27 18:35:08,461: INFO: common: created directory at: artifacts/prepare_base_model]
[2024-03-27 18:35:08,962: WARNING: saving_utils: Compiled the loaded model, but the compiled metrics have yet to be built. `model.compile_metrics` will be empty until you train or evaluate the model.]
[2024-03-27 18:35:09,351: INFO: stage_02_prepare_base_model: >>>>>> stage Prepare base model completed <<<<<<

x==========x]
[2024-03-27 18:35:17,964: INFO: stage_03_model_training: *******************]
[2024-03-27 18:35:17,965: INFO: stage_03_model_training: >>>>>> stage Training started <<<<<<]
[2024-03-27 18:35:17,968: INFO: common: yaml file: config\config.yaml loaded successfully]
[2024-03-27 18:35:17,970: INFO: common: yaml file: params.yaml loaded successfully]
[2024-03-27 18:35:17,971: INFO: common: created directory at: artifacts]
[2024-03-27 18:35:17,972: INFO: common: created directory at: artifacts\training]
[2024-03-27 18:36:34,751: INFO: stage_03_model_training: >>>>>> stage Training completed <<<<<<

x==========x]
[2024-03-27 18:36:44,615: INFO: stage_04_model_evaluation: *******************]
[2024-03-27 18:36:44,616: INFO: stage_04_model_evaluation: >>>>>> stage Evaluation stage started <<<<<<]
[2024-03-27 18:36:44,619: INFO: common: yaml file: config\config.yaml loaded successfully]
[2024-03-27 18:36:44,621: INFO: common: yaml file: params.yaml loaded successfully]
[2024-03-27 18:36:44,622: INFO: common: created directory at: artifacts]
[2024-03-27 18:37:11,620: INFO: common: json file saved at: scores.json]
[2024-03-27 18:37:11,622: INFO: common: json file saved at: scores.json]
[2024-03-27 18:37:11,622: INFO: stage_04_model_evaluation: >>>>>> stage Evaluation stage completed <<<<<<

x==========x]
[2024-03-27 19:30:54,267: INFO: _internal: [31m[1mWARNING: This is a development server. Do not use it in a production deployment. Use a production WSGI server instead.[0m
 * Running on all addresses (0.0.0.0)
 * Running on http://127.0.0.1:7000
 * Running on http://192.168.1.5:7000]
[2024-03-27 19:30:54,310: INFO: _internal: [33mPress CTRL+C to quit[0m]
[2024-03-27 19:32:29,862: INFO: _internal: 127.0.0.1 - - [27/Mar/2024 19:32:29] "GET / HTTP/1.1" 200 -]
[2024-03-27 19:33:20,620: ERROR: app: Exception on /predict [POST]]
Traceback (most recent call last):
  File "D:\Pakshal_Jain\anaconda3\envs\kidney_disease\lib\site-packages\flask\app.py", line 2190, in wsgi_app
    response = self.full_dispatch_request()
  File "D:\Pakshal_Jain\anaconda3\envs\kidney_disease\lib\site-packages\flask\app.py", line 1486, in full_dispatch_request
    rv = self.handle_user_exception(e)
  File "D:\Pakshal_Jain\anaconda3\envs\kidney_disease\lib\site-packages\flask_cors\extension.py", line 176, in wrapped_function
    return cors_after_request(app.make_response(f(*args, **kwargs)))
  File "D:\Pakshal_Jain\anaconda3\envs\kidney_disease\lib\site-packages\flask\app.py", line 1484, in full_dispatch_request
    rv = self.dispatch_request()
  File "D:\Pakshal_Jain\anaconda3\envs\kidney_disease\lib\site-packages\flask\app.py", line 1469, in dispatch_request
    return self.ensure_sync(self.view_functions[rule.endpoint])(**view_args)
  File "D:\Pakshal_Jain\anaconda3\envs\kidney_disease\lib\site-packages\flask_cors\decorator.py", line 130, in wrapped_function
    resp = make_response(f(*args, **kwargs))
  File "app.py", line 42, in predictRoute
    result = clApp.classifier.predict()
  File "d:\projects\kidney-disease-classification\src\cnnClassifier\pipeline\prediction.py", line 17, in predict
    test_image = np.expand.dims(test_image, axis=1)
  File "C:\Users\Pakshal Jain\AppData\Roaming\Python\Python38\site-packages\numpy\__init__.py", line 311, in __getattr__
    raise AttributeError("module {!r} has no attribute "
AttributeError: module 'numpy' has no attribute 'expand'
[2024-03-27 19:33:20,640: INFO: _internal: 127.0.0.1 - - [27/Mar/2024 19:33:20] "[35m[1mPOST /predict HTTP/1.1[0m" 500 -]
[2024-03-27 19:34:27,256: INFO: _internal: 127.0.0.1 - - [27/Mar/2024 19:34:27] "GET / HTTP/1.1" 200 -]
[2024-03-27 19:34:39,284: ERROR: app: Exception on /predict [POST]]
Traceback (most recent call last):
  File "D:\Pakshal_Jain\anaconda3\envs\kidney_disease\lib\site-packages\flask\app.py", line 2190, in wsgi_app
    response = self.full_dispatch_request()
  File "D:\Pakshal_Jain\anaconda3\envs\kidney_disease\lib\site-packages\flask\app.py", line 1486, in full_dispatch_request
    rv = self.handle_user_exception(e)
  File "D:\Pakshal_Jain\anaconda3\envs\kidney_disease\lib\site-packages\flask_cors\extension.py", line 176, in wrapped_function
    return cors_after_request(app.make_response(f(*args, **kwargs)))
  File "D:\Pakshal_Jain\anaconda3\envs\kidney_disease\lib\site-packages\flask\app.py", line 1484, in full_dispatch_request
    rv = self.dispatch_request()
  File "D:\Pakshal_Jain\anaconda3\envs\kidney_disease\lib\site-packages\flask\app.py", line 1469, in dispatch_request
    return self.ensure_sync(self.view_functions[rule.endpoint])(**view_args)
  File "D:\Pakshal_Jain\anaconda3\envs\kidney_disease\lib\site-packages\flask_cors\decorator.py", line 130, in wrapped_function
    resp = make_response(f(*args, **kwargs))
  File "app.py", line 42, in predictRoute
    result = clApp.classifier.predict()
  File "d:\projects\kidney-disease-classification\src\cnnClassifier\pipeline\prediction.py", line 17, in predict
    test_image = np.expand.dims(test_image, axis=1)
  File "C:\Users\Pakshal Jain\AppData\Roaming\Python\Python38\site-packages\numpy\__init__.py", line 311, in __getattr__
    raise AttributeError("module {!r} has no attribute "
AttributeError: module 'numpy' has no attribute 'expand'
[2024-03-27 19:34:39,289: INFO: _internal: 127.0.0.1 - - [27/Mar/2024 19:34:39] "[35m[1mPOST /predict HTTP/1.1[0m" 500 -]
[2024-03-27 19:39:07,197: INFO: _internal: [31m[1mWARNING: This is a development server. Do not use it in a production deployment. Use a production WSGI server instead.[0m
 * Running on all addresses (0.0.0.0)
 * Running on http://127.0.0.1:7000
 * Running on http://192.168.1.5:7000]
[2024-03-27 19:39:07,198: INFO: _internal: [33mPress CTRL+C to quit[0m]
[2024-03-27 19:39:27,733: INFO: _internal: 127.0.0.1 - - [27/Mar/2024 19:39:27] "GET / HTTP/1.1" 200 -]
[2024-03-27 19:39:39,578: ERROR: app: Exception on /predict [POST]]
Traceback (most recent call last):
  File "D:\Pakshal_Jain\anaconda3\envs\kidney_disease\lib\site-packages\flask\app.py", line 2190, in wsgi_app
    response = self.full_dispatch_request()
  File "D:\Pakshal_Jain\anaconda3\envs\kidney_disease\lib\site-packages\flask\app.py", line 1486, in full_dispatch_request
    rv = self.handle_user_exception(e)
  File "D:\Pakshal_Jain\anaconda3\envs\kidney_disease\lib\site-packages\flask_cors\extension.py", line 176, in wrapped_function
    return cors_after_request(app.make_response(f(*args, **kwargs)))
  File "D:\Pakshal_Jain\anaconda3\envs\kidney_disease\lib\site-packages\flask\app.py", line 1484, in full_dispatch_request
    rv = self.dispatch_request()
  File "D:\Pakshal_Jain\anaconda3\envs\kidney_disease\lib\site-packages\flask\app.py", line 1469, in dispatch_request
    return self.ensure_sync(self.view_functions[rule.endpoint])(**view_args)
  File "D:\Pakshal_Jain\anaconda3\envs\kidney_disease\lib\site-packages\flask_cors\decorator.py", line 130, in wrapped_function
    resp = make_response(f(*args, **kwargs))
  File "app.py", line 42, in predictRoute
    result = clApp.classifier.predict()
  File "d:\projects\kidney-disease-classification\src\cnnClassifier\pipeline\prediction.py", line 18, in predict
    result = np.argmax(model.predict(test_image), axis=1)
  File "D:\Pakshal_Jain\anaconda3\envs\kidney_disease\lib\site-packages\keras\utils\traceback_utils.py", line 70, in error_handler
    raise e.with_traceback(filtered_tb) from None
  File "C:\Users\PAKSHA~1\AppData\Local\Temp\__autograph_generated_filemq42mkwi.py", line 15, in tf__predict_function
    retval_ = ag__.converted_call(ag__.ld(step_function), (ag__.ld(self), ag__.ld(iterator)), None, fscope)
ValueError: in user code:

    File "D:\Pakshal_Jain\anaconda3\envs\kidney_disease\lib\site-packages\keras\engine\training.py", line 2169, in predict_function  *
        return step_function(self, iterator)
    File "D:\Pakshal_Jain\anaconda3\envs\kidney_disease\lib\site-packages\keras\engine\training.py", line 2155, in step_function  **
        outputs = model.distribute_strategy.run(run_step, args=(data,))
    File "D:\Pakshal_Jain\anaconda3\envs\kidney_disease\lib\site-packages\keras\engine\training.py", line 2143, in run_step  **
        outputs = model.predict_step(data)
    File "D:\Pakshal_Jain\anaconda3\envs\kidney_disease\lib\site-packages\keras\engine\training.py", line 2111, in predict_step
        return self(x, training=False)
    File "D:\Pakshal_Jain\anaconda3\envs\kidney_disease\lib\site-packages\keras\utils\traceback_utils.py", line 70, in error_handler
        raise e.with_traceback(filtered_tb) from None
    File "D:\Pakshal_Jain\anaconda3\envs\kidney_disease\lib\site-packages\keras\engine\input_spec.py", line 298, in assert_input_compatibility
        raise ValueError(

    ValueError: Input 0 of layer "model" is incompatible with the layer: expected shape=(None, 224, 224, 3), found shape=(32, 1, 224, 3)

[2024-03-27 19:39:39,632: INFO: _internal: 127.0.0.1 - - [27/Mar/2024 19:39:39] "[35m[1mPOST /predict HTTP/1.1[0m" 500 -]
[2024-03-27 19:40:40,751: INFO: _internal: 127.0.0.1 - - [27/Mar/2024 19:40:40] "GET / HTTP/1.1" 200 -]
[2024-03-27 19:40:52,871: ERROR: app: Exception on /predict [POST]]
Traceback (most recent call last):
  File "D:\Pakshal_Jain\anaconda3\envs\kidney_disease\lib\site-packages\flask\app.py", line 2190, in wsgi_app
    response = self.full_dispatch_request()
  File "D:\Pakshal_Jain\anaconda3\envs\kidney_disease\lib\site-packages\flask\app.py", line 1486, in full_dispatch_request
    rv = self.handle_user_exception(e)
  File "D:\Pakshal_Jain\anaconda3\envs\kidney_disease\lib\site-packages\flask_cors\extension.py", line 176, in wrapped_function
    return cors_after_request(app.make_response(f(*args, **kwargs)))
  File "D:\Pakshal_Jain\anaconda3\envs\kidney_disease\lib\site-packages\flask\app.py", line 1484, in full_dispatch_request
    rv = self.dispatch_request()
  File "D:\Pakshal_Jain\anaconda3\envs\kidney_disease\lib\site-packages\flask\app.py", line 1469, in dispatch_request
    return self.ensure_sync(self.view_functions[rule.endpoint])(**view_args)
  File "D:\Pakshal_Jain\anaconda3\envs\kidney_disease\lib\site-packages\flask_cors\decorator.py", line 130, in wrapped_function
    resp = make_response(f(*args, **kwargs))
  File "app.py", line 42, in predictRoute
    result = clApp.classifier.predict()
  File "d:\projects\kidney-disease-classification\src\cnnClassifier\pipeline\prediction.py", line 18, in predict
    result = np.argmax(model.predict(test_image), axis=1)
  File "D:\Pakshal_Jain\anaconda3\envs\kidney_disease\lib\site-packages\keras\utils\traceback_utils.py", line 70, in error_handler
    raise e.with_traceback(filtered_tb) from None
  File "C:\Users\PAKSHA~1\AppData\Local\Temp\__autograph_generated_filemq42mkwi.py", line 15, in tf__predict_function
    retval_ = ag__.converted_call(ag__.ld(step_function), (ag__.ld(self), ag__.ld(iterator)), None, fscope)
ValueError: in user code:

    File "D:\Pakshal_Jain\anaconda3\envs\kidney_disease\lib\site-packages\keras\engine\training.py", line 2169, in predict_function  *
        return step_function(self, iterator)
    File "D:\Pakshal_Jain\anaconda3\envs\kidney_disease\lib\site-packages\keras\engine\training.py", line 2155, in step_function  **
        outputs = model.distribute_strategy.run(run_step, args=(data,))
    File "D:\Pakshal_Jain\anaconda3\envs\kidney_disease\lib\site-packages\keras\engine\training.py", line 2143, in run_step  **
        outputs = model.predict_step(data)
    File "D:\Pakshal_Jain\anaconda3\envs\kidney_disease\lib\site-packages\keras\engine\training.py", line 2111, in predict_step
        return self(x, training=False)
    File "D:\Pakshal_Jain\anaconda3\envs\kidney_disease\lib\site-packages\keras\utils\traceback_utils.py", line 70, in error_handler
        raise e.with_traceback(filtered_tb) from None
    File "D:\Pakshal_Jain\anaconda3\envs\kidney_disease\lib\site-packages\keras\engine\input_spec.py", line 298, in assert_input_compatibility
        raise ValueError(

    ValueError: Input 0 of layer "model" is incompatible with the layer: expected shape=(None, 224, 224, 3), found shape=(32, 1, 224, 3)

[2024-03-27 19:40:52,880: INFO: _internal: 127.0.0.1 - - [27/Mar/2024 19:40:52] "[35m[1mPOST /predict HTTP/1.1[0m" 500 -]
[2024-03-27 19:47:07,717: INFO: _internal: [31m[1mWARNING: This is a development server. Do not use it in a production deployment. Use a production WSGI server instead.[0m
 * Running on all addresses (0.0.0.0)
 * Running on http://127.0.0.1:7000
 * Running on http://192.168.1.5:7000]
[2024-03-27 19:47:07,718: INFO: _internal: [33mPress CTRL+C to quit[0m]
[2024-03-27 19:47:12,054: INFO: _internal: 127.0.0.1 - - [27/Mar/2024 19:47:12] "GET / HTTP/1.1" 200 -]
[2024-03-27 19:47:19,656: ERROR: app: Exception on /predict [POST]]
Traceback (most recent call last):
  File "D:\Pakshal_Jain\anaconda3\envs\kidney_disease\lib\site-packages\flask\app.py", line 2190, in wsgi_app
    response = self.full_dispatch_request()
  File "D:\Pakshal_Jain\anaconda3\envs\kidney_disease\lib\site-packages\flask\app.py", line 1486, in full_dispatch_request
    rv = self.handle_user_exception(e)
  File "D:\Pakshal_Jain\anaconda3\envs\kidney_disease\lib\site-packages\flask_cors\extension.py", line 176, in wrapped_function
    return cors_after_request(app.make_response(f(*args, **kwargs)))
  File "D:\Pakshal_Jain\anaconda3\envs\kidney_disease\lib\site-packages\flask\app.py", line 1484, in full_dispatch_request
    rv = self.dispatch_request()
  File "D:\Pakshal_Jain\anaconda3\envs\kidney_disease\lib\site-packages\flask\app.py", line 1469, in dispatch_request
    return self.ensure_sync(self.view_functions[rule.endpoint])(**view_args)
  File "D:\Pakshal_Jain\anaconda3\envs\kidney_disease\lib\site-packages\flask_cors\decorator.py", line 130, in wrapped_function
    resp = make_response(f(*args, **kwargs))
  File "app.py", line 42, in predictRoute
    result = clApp.classifier.predict()
  File "d:\projects\kidney-disease-classification\src\cnnClassifier\pipeline\prediction.py", line 23, in predict
    result = np.argmax(model.predict(test_image), axis=1)
  File "D:\Pakshal_Jain\anaconda3\envs\kidney_disease\lib\site-packages\keras\utils\traceback_utils.py", line 70, in error_handler
    raise e.with_traceback(filtered_tb) from None
  File "C:\Users\PAKSHA~1\AppData\Local\Temp\__autograph_generated_filejqic8tsl.py", line 15, in tf__predict_function
    retval_ = ag__.converted_call(ag__.ld(step_function), (ag__.ld(self), ag__.ld(iterator)), None, fscope)
ValueError: in user code:

    File "D:\Pakshal_Jain\anaconda3\envs\kidney_disease\lib\site-packages\keras\engine\training.py", line 2169, in predict_function  *
        return step_function(self, iterator)
    File "D:\Pakshal_Jain\anaconda3\envs\kidney_disease\lib\site-packages\keras\engine\training.py", line 2155, in step_function  **
        outputs = model.distribute_strategy.run(run_step, args=(data,))
    File "D:\Pakshal_Jain\anaconda3\envs\kidney_disease\lib\site-packages\keras\engine\training.py", line 2143, in run_step  **
        outputs = model.predict_step(data)
    File "D:\Pakshal_Jain\anaconda3\envs\kidney_disease\lib\site-packages\keras\engine\training.py", line 2111, in predict_step
        return self(x, training=False)
    File "D:\Pakshal_Jain\anaconda3\envs\kidney_disease\lib\site-packages\keras\utils\traceback_utils.py", line 70, in error_handler
        raise e.with_traceback(filtered_tb) from None
    File "D:\Pakshal_Jain\anaconda3\envs\kidney_disease\lib\site-packages\keras\engine\input_spec.py", line 298, in assert_input_compatibility
        raise ValueError(

    ValueError: Input 0 of layer "model" is incompatible with the layer: expected shape=(None, 224, 224, 3), found shape=(32, 1, 224, 3)

[2024-03-27 19:47:19,844: INFO: _internal: 127.0.0.1 - - [27/Mar/2024 19:47:19] "[35m[1mPOST /predict HTTP/1.1[0m" 500 -]
[2024-03-27 20:32:13,277: INFO: _internal: [31m[1mWARNING: This is a development server. Do not use it in a production deployment. Use a production WSGI server instead.[0m
 * Running on all addresses (0.0.0.0)
 * Running on http://127.0.0.1:7000
 * Running on http://192.168.1.5:7000]
[2024-03-27 20:32:13,277: INFO: _internal: [33mPress CTRL+C to quit[0m]
[2024-03-27 20:32:22,199: INFO: _internal: 127.0.0.1 - - [27/Mar/2024 20:32:22] "GET / HTTP/1.1" 200 -]
[2024-03-27 20:33:28,433: ERROR: app: Exception on /predict [POST]]
Traceback (most recent call last):
  File "D:\Pakshal_Jain\anaconda3\envs\kidney_disease\lib\site-packages\flask\app.py", line 2190, in wsgi_app
    response = self.full_dispatch_request()
  File "D:\Pakshal_Jain\anaconda3\envs\kidney_disease\lib\site-packages\flask\app.py", line 1486, in full_dispatch_request
    rv = self.handle_user_exception(e)
  File "D:\Pakshal_Jain\anaconda3\envs\kidney_disease\lib\site-packages\flask_cors\extension.py", line 176, in wrapped_function
    return cors_after_request(app.make_response(f(*args, **kwargs)))
  File "D:\Pakshal_Jain\anaconda3\envs\kidney_disease\lib\site-packages\flask\app.py", line 1484, in full_dispatch_request
    rv = self.dispatch_request()
  File "D:\Pakshal_Jain\anaconda3\envs\kidney_disease\lib\site-packages\flask\app.py", line 1469, in dispatch_request
    return self.ensure_sync(self.view_functions[rule.endpoint])(**view_args)
  File "D:\Pakshal_Jain\anaconda3\envs\kidney_disease\lib\site-packages\flask_cors\decorator.py", line 130, in wrapped_function
    resp = make_response(f(*args, **kwargs))
  File "app.py", line 42, in predictRoute
    result = clApp.classifier.predict()
  File "d:\projects\kidney-disease-classification\src\cnnClassifier\pipeline\prediction.py", line 26, in predict
    result = np.argmax(model.predict(test_image), axis=1)
  File "D:\Pakshal_Jain\anaconda3\envs\kidney_disease\lib\site-packages\keras\utils\traceback_utils.py", line 70, in error_handler
    raise e.with_traceback(filtered_tb) from None
  File "C:\Users\PAKSHA~1\AppData\Local\Temp\__autograph_generated_fileigmxukt7.py", line 15, in tf__predict_function
    retval_ = ag__.converted_call(ag__.ld(step_function), (ag__.ld(self), ag__.ld(iterator)), None, fscope)
ValueError: in user code:

    File "D:\Pakshal_Jain\anaconda3\envs\kidney_disease\lib\site-packages\keras\engine\training.py", line 2169, in predict_function  *
        return step_function(self, iterator)
    File "D:\Pakshal_Jain\anaconda3\envs\kidney_disease\lib\site-packages\keras\engine\training.py", line 2155, in step_function  **
        outputs = model.distribute_strategy.run(run_step, args=(data,))
    File "D:\Pakshal_Jain\anaconda3\envs\kidney_disease\lib\site-packages\keras\engine\training.py", line 2143, in run_step  **
        outputs = model.predict_step(data)
    File "D:\Pakshal_Jain\anaconda3\envs\kidney_disease\lib\site-packages\keras\engine\training.py", line 2111, in predict_step
        return self(x, training=False)
    File "D:\Pakshal_Jain\anaconda3\envs\kidney_disease\lib\site-packages\keras\utils\traceback_utils.py", line 70, in error_handler
        raise e.with_traceback(filtered_tb) from None
    File "D:\Pakshal_Jain\anaconda3\envs\kidney_disease\lib\site-packages\keras\engine\input_spec.py", line 298, in assert_input_compatibility
        raise ValueError(

    ValueError: Input 0 of layer "model" is incompatible with the layer: expected shape=(None, 224, 224, 3), found shape=(32, 1, 224, 3)

[2024-03-27 20:33:28,530: INFO: _internal: 127.0.0.1 - - [27/Mar/2024 20:33:28] "[35m[1mPOST /predict HTTP/1.1[0m" 500 -]
[2024-03-27 20:35:24,600: INFO: _internal: [31m[1mWARNING: This is a development server. Do not use it in a production deployment. Use a production WSGI server instead.[0m
 * Running on all addresses (0.0.0.0)
 * Running on http://127.0.0.1:7000
 * Running on http://192.168.1.5:7000]
[2024-03-27 20:35:24,601: INFO: _internal: [33mPress CTRL+C to quit[0m]
[2024-03-27 20:35:24,761: INFO: _internal: 127.0.0.1 - - [27/Mar/2024 20:35:24] "GET / HTTP/1.1" 200 -]
[2024-03-27 20:35:38,505: ERROR: app: Exception on /predict [POST]]
Traceback (most recent call last):
  File "D:\Pakshal_Jain\anaconda3\envs\kidney_disease\lib\site-packages\flask\app.py", line 2190, in wsgi_app
    response = self.full_dispatch_request()
  File "D:\Pakshal_Jain\anaconda3\envs\kidney_disease\lib\site-packages\flask\app.py", line 1486, in full_dispatch_request
    rv = self.handle_user_exception(e)
  File "D:\Pakshal_Jain\anaconda3\envs\kidney_disease\lib\site-packages\flask_cors\extension.py", line 176, in wrapped_function
    return cors_after_request(app.make_response(f(*args, **kwargs)))
  File "D:\Pakshal_Jain\anaconda3\envs\kidney_disease\lib\site-packages\flask\app.py", line 1484, in full_dispatch_request
    rv = self.dispatch_request()
  File "D:\Pakshal_Jain\anaconda3\envs\kidney_disease\lib\site-packages\flask\app.py", line 1469, in dispatch_request
    return self.ensure_sync(self.view_functions[rule.endpoint])(**view_args)
  File "D:\Pakshal_Jain\anaconda3\envs\kidney_disease\lib\site-packages\flask_cors\decorator.py", line 130, in wrapped_function
    resp = make_response(f(*args, **kwargs))
  File "app.py", line 42, in predictRoute
    result = clApp.classifier.predict()
  File "d:\projects\kidney-disease-classification\src\cnnClassifier\pipeline\prediction.py", line 23, in predict
    test_image = tf.image.resize(test_image, (-1,224,224,3))
  File "D:\Pakshal_Jain\anaconda3\envs\kidney_disease\lib\site-packages\tensorflow\python\util\traceback_utils.py", line 153, in error_handler
    raise e.with_traceback(filtered_tb) from None
  File "D:\Pakshal_Jain\anaconda3\envs\kidney_disease\lib\site-packages\tensorflow\python\ops\image_ops_impl.py", line 1459, in _resize_images_common
    raise ValueError('\'size\' must be a 1-D Tensor of 2 elements: '
ValueError: 'size' must be a 1-D Tensor of 2 elements: new_height, new_width
[2024-03-27 20:35:38,609: INFO: _internal: 127.0.0.1 - - [27/Mar/2024 20:35:38] "[35m[1mPOST /predict HTTP/1.1[0m" 500 -]
[2024-03-27 20:37:26,244: INFO: _internal: [31m[1mWARNING: This is a development server. Do not use it in a production deployment. Use a production WSGI server instead.[0m
 * Running on all addresses (0.0.0.0)
 * Running on http://127.0.0.1:7000
 * Running on http://192.168.1.5:7000]
[2024-03-27 20:37:26,246: INFO: _internal: [33mPress CTRL+C to quit[0m]
[2024-03-27 20:37:26,303: INFO: _internal: 127.0.0.1 - - [27/Mar/2024 20:37:26] "GET / HTTP/1.1" 200 -]
[2024-03-27 20:37:34,694: ERROR: app: Exception on /predict [POST]]
Traceback (most recent call last):
  File "D:\Pakshal_Jain\anaconda3\envs\kidney_disease\lib\site-packages\flask\app.py", line 2190, in wsgi_app
    response = self.full_dispatch_request()
  File "D:\Pakshal_Jain\anaconda3\envs\kidney_disease\lib\site-packages\flask\app.py", line 1486, in full_dispatch_request
    rv = self.handle_user_exception(e)
  File "D:\Pakshal_Jain\anaconda3\envs\kidney_disease\lib\site-packages\flask_cors\extension.py", line 176, in wrapped_function
    return cors_after_request(app.make_response(f(*args, **kwargs)))
  File "D:\Pakshal_Jain\anaconda3\envs\kidney_disease\lib\site-packages\flask\app.py", line 1484, in full_dispatch_request
    rv = self.dispatch_request()
  File "D:\Pakshal_Jain\anaconda3\envs\kidney_disease\lib\site-packages\flask\app.py", line 1469, in dispatch_request
    return self.ensure_sync(self.view_functions[rule.endpoint])(**view_args)
  File "D:\Pakshal_Jain\anaconda3\envs\kidney_disease\lib\site-packages\flask_cors\decorator.py", line 130, in wrapped_function
    resp = make_response(f(*args, **kwargs))
  File "app.py", line 42, in predictRoute
    result = clApp.classifier.predict()
  File "d:\projects\kidney-disease-classification\src\cnnClassifier\pipeline\prediction.py", line 27, in predict
    result = np.argmax(model.predict(test_image), axis=1)
  File "D:\Pakshal_Jain\anaconda3\envs\kidney_disease\lib\site-packages\keras\utils\traceback_utils.py", line 70, in error_handler
    raise e.with_traceback(filtered_tb) from None
  File "C:\Users\PAKSHA~1\AppData\Local\Temp\__autograph_generated_filexd9uay59.py", line 15, in tf__predict_function
    retval_ = ag__.converted_call(ag__.ld(step_function), (ag__.ld(self), ag__.ld(iterator)), None, fscope)
ValueError: in user code:

    File "D:\Pakshal_Jain\anaconda3\envs\kidney_disease\lib\site-packages\keras\engine\training.py", line 2169, in predict_function  *
        return step_function(self, iterator)
    File "D:\Pakshal_Jain\anaconda3\envs\kidney_disease\lib\site-packages\keras\engine\training.py", line 2155, in step_function  **
        outputs = model.distribute_strategy.run(run_step, args=(data,))
    File "D:\Pakshal_Jain\anaconda3\envs\kidney_disease\lib\site-packages\keras\engine\training.py", line 2143, in run_step  **
        outputs = model.predict_step(data)
    File "D:\Pakshal_Jain\anaconda3\envs\kidney_disease\lib\site-packages\keras\engine\training.py", line 2111, in predict_step
        return self(x, training=False)
    File "D:\Pakshal_Jain\anaconda3\envs\kidney_disease\lib\site-packages\keras\utils\traceback_utils.py", line 70, in error_handler
        raise e.with_traceback(filtered_tb) from None
    File "D:\Pakshal_Jain\anaconda3\envs\kidney_disease\lib\site-packages\keras\engine\input_spec.py", line 298, in assert_input_compatibility
        raise ValueError(

    ValueError: Input 0 of layer "model" is incompatible with the layer: expected shape=(None, 224, 224, 3), found shape=(32, 1, 224, 3)

[2024-03-27 20:37:34,706: INFO: _internal: 127.0.0.1 - - [27/Mar/2024 20:37:34] "[35m[1mPOST /predict HTTP/1.1[0m" 500 -]
[2024-03-27 20:38:46,780: INFO: _internal: [31m[1mWARNING: This is a development server. Do not use it in a production deployment. Use a production WSGI server instead.[0m
 * Running on all addresses (0.0.0.0)
 * Running on http://127.0.0.1:7000
 * Running on http://192.168.1.5:7000]
[2024-03-27 20:38:46,781: INFO: _internal: [33mPress CTRL+C to quit[0m]
[2024-03-27 20:38:47,738: INFO: _internal: 127.0.0.1 - - [27/Mar/2024 20:38:47] "GET / HTTP/1.1" 200 -]
[2024-03-27 20:38:55,195: ERROR: app: Exception on /predict [POST]]
Traceback (most recent call last):
  File "D:\Pakshal_Jain\anaconda3\envs\kidney_disease\lib\site-packages\flask\app.py", line 2190, in wsgi_app
    response = self.full_dispatch_request()
  File "D:\Pakshal_Jain\anaconda3\envs\kidney_disease\lib\site-packages\flask\app.py", line 1486, in full_dispatch_request
    rv = self.handle_user_exception(e)
  File "D:\Pakshal_Jain\anaconda3\envs\kidney_disease\lib\site-packages\flask_cors\extension.py", line 176, in wrapped_function
    return cors_after_request(app.make_response(f(*args, **kwargs)))
  File "D:\Pakshal_Jain\anaconda3\envs\kidney_disease\lib\site-packages\flask\app.py", line 1484, in full_dispatch_request
    rv = self.dispatch_request()
  File "D:\Pakshal_Jain\anaconda3\envs\kidney_disease\lib\site-packages\flask\app.py", line 1469, in dispatch_request
    return self.ensure_sync(self.view_functions[rule.endpoint])(**view_args)
  File "D:\Pakshal_Jain\anaconda3\envs\kidney_disease\lib\site-packages\flask_cors\decorator.py", line 130, in wrapped_function
    resp = make_response(f(*args, **kwargs))
  File "app.py", line 42, in predictRoute
    result = clApp.classifier.predict()
  File "d:\projects\kidney-disease-classification\src\cnnClassifier\pipeline\prediction.py", line 27, in predict
    result = np.argmax(model.predict(test_image), axis=1)
  File "D:\Pakshal_Jain\anaconda3\envs\kidney_disease\lib\site-packages\keras\utils\traceback_utils.py", line 70, in error_handler
    raise e.with_traceback(filtered_tb) from None
  File "C:\Users\PAKSHA~1\AppData\Local\Temp\__autograph_generated_fileseiqcop2.py", line 15, in tf__predict_function
    retval_ = ag__.converted_call(ag__.ld(step_function), (ag__.ld(self), ag__.ld(iterator)), None, fscope)
ValueError: in user code:

    File "D:\Pakshal_Jain\anaconda3\envs\kidney_disease\lib\site-packages\keras\engine\training.py", line 2169, in predict_function  *
        return step_function(self, iterator)
    File "D:\Pakshal_Jain\anaconda3\envs\kidney_disease\lib\site-packages\keras\engine\training.py", line 2155, in step_function  **
        outputs = model.distribute_strategy.run(run_step, args=(data,))
    File "D:\Pakshal_Jain\anaconda3\envs\kidney_disease\lib\site-packages\keras\engine\training.py", line 2143, in run_step  **
        outputs = model.predict_step(data)
    File "D:\Pakshal_Jain\anaconda3\envs\kidney_disease\lib\site-packages\keras\engine\training.py", line 2111, in predict_step
        return self(x, training=False)
    File "D:\Pakshal_Jain\anaconda3\envs\kidney_disease\lib\site-packages\keras\utils\traceback_utils.py", line 70, in error_handler
        raise e.with_traceback(filtered_tb) from None
    File "D:\Pakshal_Jain\anaconda3\envs\kidney_disease\lib\site-packages\keras\engine\input_spec.py", line 298, in assert_input_compatibility
        raise ValueError(

    ValueError: Input 0 of layer "model" is incompatible with the layer: expected shape=(None, 224, 224, 3), found shape=(32, 1, 224, 3)

[2024-03-27 20:38:55,205: INFO: _internal: 127.0.0.1 - - [27/Mar/2024 20:38:55] "[35m[1mPOST /predict HTTP/1.1[0m" 500 -]
[2024-03-27 20:40:13,756: INFO: _internal: [31m[1mWARNING: This is a development server. Do not use it in a production deployment. Use a production WSGI server instead.[0m
 * Running on all addresses (0.0.0.0)
 * Running on http://127.0.0.1:7000
 * Running on http://192.168.1.5:7000]
[2024-03-27 20:40:13,757: INFO: _internal: [33mPress CTRL+C to quit[0m]
[2024-03-27 20:40:13,918: INFO: _internal: 127.0.0.1 - - [27/Mar/2024 20:40:13] "GET / HTTP/1.1" 200 -]
[2024-03-27 20:40:20,464: ERROR: app: Exception on /predict [POST]]
Traceback (most recent call last):
  File "D:\Pakshal_Jain\anaconda3\envs\kidney_disease\lib\site-packages\flask\app.py", line 2190, in wsgi_app
    response = self.full_dispatch_request()
  File "D:\Pakshal_Jain\anaconda3\envs\kidney_disease\lib\site-packages\flask\app.py", line 1486, in full_dispatch_request
    rv = self.handle_user_exception(e)
  File "D:\Pakshal_Jain\anaconda3\envs\kidney_disease\lib\site-packages\flask_cors\extension.py", line 176, in wrapped_function
    return cors_after_request(app.make_response(f(*args, **kwargs)))
  File "D:\Pakshal_Jain\anaconda3\envs\kidney_disease\lib\site-packages\flask\app.py", line 1484, in full_dispatch_request
    rv = self.dispatch_request()
  File "D:\Pakshal_Jain\anaconda3\envs\kidney_disease\lib\site-packages\flask\app.py", line 1469, in dispatch_request
    return self.ensure_sync(self.view_functions[rule.endpoint])(**view_args)
  File "D:\Pakshal_Jain\anaconda3\envs\kidney_disease\lib\site-packages\flask_cors\decorator.py", line 130, in wrapped_function
    resp = make_response(f(*args, **kwargs))
  File "app.py", line 42, in predictRoute
    result = clApp.classifier.predict()
  File "d:\projects\kidney-disease-classification\src\cnnClassifier\pipeline\prediction.py", line 27, in predict
    result = np.argmax(model.predict(test_image), axis=1)
  File "D:\Pakshal_Jain\anaconda3\envs\kidney_disease\lib\site-packages\keras\utils\traceback_utils.py", line 70, in error_handler
    raise e.with_traceback(filtered_tb) from None
  File "C:\Users\PAKSHA~1\AppData\Local\Temp\__autograph_generated_file0e8tkqp9.py", line 15, in tf__predict_function
    retval_ = ag__.converted_call(ag__.ld(step_function), (ag__.ld(self), ag__.ld(iterator)), None, fscope)
ValueError: in user code:

    File "D:\Pakshal_Jain\anaconda3\envs\kidney_disease\lib\site-packages\keras\engine\training.py", line 2169, in predict_function  *
        return step_function(self, iterator)
    File "D:\Pakshal_Jain\anaconda3\envs\kidney_disease\lib\site-packages\keras\engine\training.py", line 2155, in step_function  **
        outputs = model.distribute_strategy.run(run_step, args=(data,))
    File "D:\Pakshal_Jain\anaconda3\envs\kidney_disease\lib\site-packages\keras\engine\training.py", line 2143, in run_step  **
        outputs = model.predict_step(data)
    File "D:\Pakshal_Jain\anaconda3\envs\kidney_disease\lib\site-packages\keras\engine\training.py", line 2111, in predict_step
        return self(x, training=False)
    File "D:\Pakshal_Jain\anaconda3\envs\kidney_disease\lib\site-packages\keras\utils\traceback_utils.py", line 70, in error_handler
        raise e.with_traceback(filtered_tb) from None
    File "D:\Pakshal_Jain\anaconda3\envs\kidney_disease\lib\site-packages\keras\engine\input_spec.py", line 298, in assert_input_compatibility
        raise ValueError(

    ValueError: Input 0 of layer "model" is incompatible with the layer: expected shape=(None, 224, 224, 3), found shape=(32, 224, 3)

[2024-03-27 20:40:20,520: INFO: _internal: 127.0.0.1 - - [27/Mar/2024 20:40:20] "[35m[1mPOST /predict HTTP/1.1[0m" 500 -]
[2024-03-27 20:45:07,531: INFO: _internal: [31m[1mWARNING: This is a development server. Do not use it in a production deployment. Use a production WSGI server instead.[0m
 * Running on all addresses (0.0.0.0)
 * Running on http://127.0.0.1:7000
 * Running on http://192.168.1.5:7000]
[2024-03-27 20:45:07,532: INFO: _internal: [33mPress CTRL+C to quit[0m]
[2024-03-27 20:45:10,356: INFO: _internal: 127.0.0.1 - - [27/Mar/2024 20:45:10] "GET / HTTP/1.1" 200 -]
[2024-03-27 20:45:19,197: ERROR: app: Exception on /predict [POST]]
Traceback (most recent call last):
  File "D:\Pakshal_Jain\anaconda3\envs\kidney_disease\lib\site-packages\flask\app.py", line 2190, in wsgi_app
    response = self.full_dispatch_request()
  File "D:\Pakshal_Jain\anaconda3\envs\kidney_disease\lib\site-packages\flask\app.py", line 1486, in full_dispatch_request
    rv = self.handle_user_exception(e)
  File "D:\Pakshal_Jain\anaconda3\envs\kidney_disease\lib\site-packages\flask_cors\extension.py", line 176, in wrapped_function
    return cors_after_request(app.make_response(f(*args, **kwargs)))
  File "D:\Pakshal_Jain\anaconda3\envs\kidney_disease\lib\site-packages\flask\app.py", line 1484, in full_dispatch_request
    rv = self.dispatch_request()
  File "D:\Pakshal_Jain\anaconda3\envs\kidney_disease\lib\site-packages\flask\app.py", line 1469, in dispatch_request
    return self.ensure_sync(self.view_functions[rule.endpoint])(**view_args)
  File "D:\Pakshal_Jain\anaconda3\envs\kidney_disease\lib\site-packages\flask_cors\decorator.py", line 130, in wrapped_function
    resp = make_response(f(*args, **kwargs))
  File "app.py", line 42, in predictRoute
    result = clApp.classifier.predict()
  File "d:\projects\kidney-disease-classification\src\cnnClassifier\pipeline\prediction.py", line 24, in predict
    test_image = tf.image.resize(test_image, (1,224,224,3))
  File "D:\Pakshal_Jain\anaconda3\envs\kidney_disease\lib\site-packages\tensorflow\python\util\traceback_utils.py", line 153, in error_handler
    raise e.with_traceback(filtered_tb) from None
  File "D:\Pakshal_Jain\anaconda3\envs\kidney_disease\lib\site-packages\tensorflow\python\ops\image_ops_impl.py", line 1459, in _resize_images_common
    raise ValueError('\'size\' must be a 1-D Tensor of 2 elements: '
ValueError: 'size' must be a 1-D Tensor of 2 elements: new_height, new_width
[2024-03-27 20:45:19,219: INFO: _internal: 127.0.0.1 - - [27/Mar/2024 20:45:19] "[35m[1mPOST /predict HTTP/1.1[0m" 500 -]
[2024-03-27 20:47:31,330: INFO: _internal: [31m[1mWARNING: This is a development server. Do not use it in a production deployment. Use a production WSGI server instead.[0m
 * Running on all addresses (0.0.0.0)
 * Running on http://127.0.0.1:7000
 * Running on http://192.168.1.5:7000]
[2024-03-27 20:47:31,725: INFO: _internal: [33mPress CTRL+C to quit[0m]
[2024-03-27 20:47:34,809: INFO: _internal: 127.0.0.1 - - [27/Mar/2024 20:47:34] "GET / HTTP/1.1" 200 -]
[2024-03-27 20:47:42,671: ERROR: app: Exception on /predict [POST]]
Traceback (most recent call last):
  File "D:\Pakshal_Jain\anaconda3\envs\kidney_disease\lib\site-packages\flask\app.py", line 2190, in wsgi_app
    response = self.full_dispatch_request()
  File "D:\Pakshal_Jain\anaconda3\envs\kidney_disease\lib\site-packages\flask\app.py", line 1486, in full_dispatch_request
    rv = self.handle_user_exception(e)
  File "D:\Pakshal_Jain\anaconda3\envs\kidney_disease\lib\site-packages\flask_cors\extension.py", line 176, in wrapped_function
    return cors_after_request(app.make_response(f(*args, **kwargs)))
  File "D:\Pakshal_Jain\anaconda3\envs\kidney_disease\lib\site-packages\flask\app.py", line 1484, in full_dispatch_request
    rv = self.dispatch_request()
  File "D:\Pakshal_Jain\anaconda3\envs\kidney_disease\lib\site-packages\flask\app.py", line 1469, in dispatch_request
    return self.ensure_sync(self.view_functions[rule.endpoint])(**view_args)
  File "D:\Pakshal_Jain\anaconda3\envs\kidney_disease\lib\site-packages\flask_cors\decorator.py", line 130, in wrapped_function
    resp = make_response(f(*args, **kwargs))
  File "app.py", line 42, in predictRoute
    result = clApp.classifier.predict()
  File "d:\projects\kidney-disease-classification\src\cnnClassifier\pipeline\prediction.py", line 26, in predict
    result = np.argmax(model.predict(test_image), axis=1)
  File "D:\Pakshal_Jain\anaconda3\envs\kidney_disease\lib\site-packages\keras\utils\traceback_utils.py", line 70, in error_handler
    raise e.with_traceback(filtered_tb) from None
  File "C:\Users\PAKSHA~1\AppData\Local\Temp\__autograph_generated_file3zlboxip.py", line 15, in tf__predict_function
    retval_ = ag__.converted_call(ag__.ld(step_function), (ag__.ld(self), ag__.ld(iterator)), None, fscope)
ValueError: in user code:

    File "D:\Pakshal_Jain\anaconda3\envs\kidney_disease\lib\site-packages\keras\engine\training.py", line 2169, in predict_function  *
        return step_function(self, iterator)
    File "D:\Pakshal_Jain\anaconda3\envs\kidney_disease\lib\site-packages\keras\engine\training.py", line 2155, in step_function  **
        outputs = model.distribute_strategy.run(run_step, args=(data,))
    File "D:\Pakshal_Jain\anaconda3\envs\kidney_disease\lib\site-packages\keras\engine\training.py", line 2143, in run_step  **
        outputs = model.predict_step(data)
    File "D:\Pakshal_Jain\anaconda3\envs\kidney_disease\lib\site-packages\keras\engine\training.py", line 2111, in predict_step
        return self(x, training=False)
    File "D:\Pakshal_Jain\anaconda3\envs\kidney_disease\lib\site-packages\keras\utils\traceback_utils.py", line 70, in error_handler
        raise e.with_traceback(filtered_tb) from None
    File "D:\Pakshal_Jain\anaconda3\envs\kidney_disease\lib\site-packages\keras\engine\input_spec.py", line 298, in assert_input_compatibility
        raise ValueError(

    ValueError: Input 0 of layer "model" is incompatible with the layer: expected shape=(None, 224, 224, 3), found shape=(32, 1, 224, 3)

[2024-03-27 20:47:42,691: INFO: _internal: 127.0.0.1 - - [27/Mar/2024 20:47:42] "[35m[1mPOST /predict HTTP/1.1[0m" 500 -]
[2024-03-27 20:50:38,120: INFO: _internal: [31m[1mWARNING: This is a development server. Do not use it in a production deployment. Use a production WSGI server instead.[0m
 * Running on all addresses (0.0.0.0)
 * Running on http://127.0.0.1:7000
 * Running on http://192.168.1.5:7000]
[2024-03-27 20:50:38,121: INFO: _internal: [33mPress CTRL+C to quit[0m]
[2024-03-27 20:50:40,111: INFO: _internal: 127.0.0.1 - - [27/Mar/2024 20:50:40] "GET / HTTP/1.1" 200 -]
[2024-03-27 20:50:46,837: ERROR: app: Exception on /predict [POST]]
Traceback (most recent call last):
  File "D:\Pakshal_Jain\anaconda3\envs\kidney_disease\lib\site-packages\flask\app.py", line 2190, in wsgi_app
    response = self.full_dispatch_request()
  File "D:\Pakshal_Jain\anaconda3\envs\kidney_disease\lib\site-packages\flask\app.py", line 1486, in full_dispatch_request
    rv = self.handle_user_exception(e)
  File "D:\Pakshal_Jain\anaconda3\envs\kidney_disease\lib\site-packages\flask_cors\extension.py", line 176, in wrapped_function
    return cors_after_request(app.make_response(f(*args, **kwargs)))
  File "D:\Pakshal_Jain\anaconda3\envs\kidney_disease\lib\site-packages\flask\app.py", line 1484, in full_dispatch_request
    rv = self.dispatch_request()
  File "D:\Pakshal_Jain\anaconda3\envs\kidney_disease\lib\site-packages\flask\app.py", line 1469, in dispatch_request
    return self.ensure_sync(self.view_functions[rule.endpoint])(**view_args)
  File "D:\Pakshal_Jain\anaconda3\envs\kidney_disease\lib\site-packages\flask_cors\decorator.py", line 130, in wrapped_function
    resp = make_response(f(*args, **kwargs))
  File "app.py", line 42, in predictRoute
    result = clApp.classifier.predict()
  File "d:\projects\kidney-disease-classification\src\cnnClassifier\pipeline\prediction.py", line 52, in predict
    model = load_model(os.path.join("model", "model.h5"))
  File "D:\Pakshal_Jain\anaconda3\envs\kidney_disease\lib\site-packages\keras\saving\saving_api.py", line 212, in load_model
    return legacy_sm_saving_lib.load_model(
  File "D:\Pakshal_Jain\anaconda3\envs\kidney_disease\lib\site-packages\keras\utils\traceback_utils.py", line 70, in error_handler
    raise e.with_traceback(filtered_tb) from None
  File "D:\Pakshal_Jain\anaconda3\envs\kidney_disease\lib\site-packages\keras\saving\legacy\save.py", line 230, in load_model
    raise IOError(
OSError: No file or directory found at model\model.h5
[2024-03-27 20:50:46,866: INFO: _internal: 127.0.0.1 - - [27/Mar/2024 20:50:46] "[35m[1mPOST /predict HTTP/1.1[0m" 500 -]
[2024-03-27 20:52:16,274: INFO: _internal: [31m[1mWARNING: This is a development server. Do not use it in a production deployment. Use a production WSGI server instead.[0m
 * Running on all addresses (0.0.0.0)
 * Running on http://127.0.0.1:7000
 * Running on http://192.168.1.5:7000]
[2024-03-27 20:52:16,275: INFO: _internal: [33mPress CTRL+C to quit[0m]
[2024-03-27 20:52:21,344: INFO: _internal: 127.0.0.1 - - [27/Mar/2024 20:52:21] "GET / HTTP/1.1" 200 -]
[2024-03-27 20:52:28,544: INFO: _internal: 127.0.0.1 - - [27/Mar/2024 20:52:28] "POST /predict HTTP/1.1" 200 -]
[2024-03-27 20:54:38,987: INFO: _internal: 127.0.0.1 - - [27/Mar/2024 20:54:38] "POST /predict HTTP/1.1" 200 -]
[2024-03-27 20:55:17,285: INFO: _internal: [31m[1mWARNING: This is a development server. Do not use it in a production deployment. Use a production WSGI server instead.[0m
 * Running on all addresses (0.0.0.0)
 * Running on http://127.0.0.1:7000
 * Running on http://192.168.1.5:7000]
[2024-03-27 20:55:17,285: INFO: _internal: [33mPress CTRL+C to quit[0m]
[2024-03-27 20:55:17,321: INFO: _internal: 127.0.0.1 - - [27/Mar/2024 20:55:17] "GET / HTTP/1.1" 200 -]
[2024-03-27 20:55:28,008: INFO: _internal: 127.0.0.1 - - [27/Mar/2024 20:55:28] "POST /predict HTTP/1.1" 200 -]
[2024-03-27 20:55:38,136: INFO: _internal: 127.0.0.1 - - [27/Mar/2024 20:55:38] "POST /predict HTTP/1.1" 200 -]
[2024-03-27 21:12:44,520: INFO: _internal: [31m[1mWARNING: This is a development server. Do not use it in a production deployment. Use a production WSGI server instead.[0m
 * Running on all addresses (0.0.0.0)
 * Running on http://127.0.0.1:7000
 * Running on http://192.168.1.5:7000]
[2024-03-27 21:12:44,521: INFO: _internal: [33mPress CTRL+C to quit[0m]
[2024-03-27 21:12:51,188: INFO: _internal: 127.0.0.1 - - [27/Mar/2024 21:12:51] "GET / HTTP/1.1" 200 -]
[2024-03-27 21:12:58,478: INFO: _internal: 127.0.0.1 - - [27/Mar/2024 21:12:58] "POST /predict HTTP/1.1" 200 -]
